<sdf version='1.7'>
  <world name='default'>
    <light name='sun' type='directional'>
      <cast_shadows>1</cast_shadows>
      <pose>0 0 10 0 -0 0</pose>
      <diffuse>0.8 0.8 0.8 1</diffuse>
      <specular>0.2 0.2 0.2 1</specular>
      <attenuation>
        <range>1000</range>
        <constant>0.9</constant>
        <linear>0.01</linear>
        <quadratic>0.001</quadratic>
      </attenuation>
      <direction>-0.5 0.1 -0.9</direction>
      <spot>
        <inner_angle>0</inner_angle>
        <outer_angle>0</outer_angle>
        <falloff>0</falloff>
      </spot>
    </light>
    <model name='ground_plane'>
      <static>1</static>
      <link name='link'>
        <collision name='collision'>
          <geometry>
            <plane>
              <normal>0 0 1</normal>
              <size>100 100</size>
            </plane>
          </geometry>
          <surface>
            <contact>
              <collide_bitmask>65535</collide_bitmask>
              <ode/>
            </contact>
            <friction>
              <ode>
                <mu>100</mu>
                <mu2>50</mu2>
              </ode>
              <torsional>
                <ode/>
              </torsional>
            </friction>
            <bounce/>
          </surface>
          <max_contacts>10</max_contacts>
        </collision>
        <visual name='visual'>
          <cast_shadows>0</cast_shadows>
          <geometry>
            <plane>
              <normal>0 0 1</normal>
              <size>100 100</size>
            </plane>
          </geometry>
          <material>
            <script>
              <uri>file://media/materials/scripts/gazebo.material</uri>
              <name>Gazebo/Grey</name>
            </script>
          </material>
        </visual>
        <self_collide>0</self_collide>
        <enable_wind>0</enable_wind>
        <kinematic>0</kinematic>
      </link>
    </model>
    <gravity>0 0 -10</gravity>
    <magnetic_field>6e-06 2.3e-05 -4.2e-05</magnetic_field>
    <atmosphere type='adiabatic'/>
    <physics type='ode'>
      <max_step_size>0.001</max_step_size>
      <real_time_factor>1</real_time_factor>
      <real_time_update_rate>1000</real_time_update_rate>
    </physics>
    <scene>
      <ambient>0.4 0.4 0.4 1</ambient>
      <background>0.7 0.7 0.7 1</background>
      <shadows>1</shadows>
    </scene>
    <wind/>
    <spherical_coordinates>
      <surface_model>EARTH_WGS84</surface_model>
      <latitude_deg>0</latitude_deg>
      <longitude_deg>0</longitude_deg>
      <elevation>0</elevation>
      <heading_deg>0</heading_deg>
    </spherical_coordinates>
    <model name='rmus_map_2'>
      <link name='link_0'>
        <inertial>
          <mass>1</mass>
          <inertia>
            <ixx>0.166667</ixx>
            <ixy>0</ixy>
            <ixz>0</ixz>
            <iyy>0.166667</iyy>
            <iyz>0</iyz>
            <izz>0.166667</izz>
          </inertia>
        </inertial>
        <pose>0 -0 0 0 -0 0</pose>
        <visual name='visual'>
          <pose>0 0 0 0 -0 0</pose>
          <geometry>
            <mesh>
              <uri>/media/tdt/YI/ZY_RoboRTS/install/genshin_simulation/share/genshin_simulation/../../../../src/genshin_simulation/world/../meshes/base_link.stl</uri>
              <scale>1 1 1</scale>
            </mesh>
          </geometry>
          <material>
            <lighting>1</lighting>
            <script>
              <uri>file://media/materials/scripts/gazebo.material</uri>
              <name>Gazebo/Grey</name>
            </script>
            <shader type='pixel'/>
          </material>
          <transparency>0</transparency>
          <cast_shadows>1</cast_shadows>
        </visual>
        <collision name='collision'>
          <laser_retro>0</laser_retro>
          <max_contacts>10</max_contacts>
          <pose>0 0 0 0 -0 0</pose>
          <geometry>
            <mesh>
              <uri>/media/tdt/YI/ZY_RoboRTS/install/genshin_simulation/share/genshin_simulation/../../../../src/genshin_simulation/world/../meshes/base_link.stl</uri>
              <scale>1 1 1</scale>
            </mesh>
          </geometry>
          <surface>
            <friction>
              <ode>
                <mu>1</mu>
                <mu2>1</mu2>
                <fdir1>0 0 0</fdir1>
                <slip1>0</slip1>
                <slip2>0</slip2>
              </ode>
              <torsional>
                <coefficient>1</coefficient>
                <patch_radius>0</patch_radius>
                <surface_radius>0</surface_radius>
                <use_patch_radius>1</use_patch_radius>
                <ode>
                  <slip>0</slip>
                </ode>
              </torsional>
            </friction>
            <bounce>
              <restitution_coefficient>0</restitution_coefficient>
              <threshold>1e+06</threshold>
            </bounce>
            <contact>
              <collide_without_contact>0</collide_without_contact>
              <collide_without_contact_bitmask>1</collide_without_contact_bitmask>
              <collide_bitmask>1</collide_bitmask>
              <ode>
                <soft_cfm>0</soft_cfm>
                <soft_erp>0.2</soft_erp>
                <kp>1e+13</kp>
                <kd>1</kd>
                <max_vel>0.01</max_vel>
                <min_depth>0</min_depth>
              </ode>
              <bullet>
                <split_impulse>1</split_impulse>
                <split_impulse_penetration_threshold>-0.01</split_impulse_penetration_threshold>
                <soft_cfm>0</soft_cfm>
                <soft_erp>0.2</soft_erp>
                <kp>1e+13</kp>
                <kd>1</kd>
              </bullet>
            </contact>
          </surface>
        </collision>
        <self_collide>0</self_collide>
        <enable_wind>0</enable_wind>
        <kinematic>0</kinematic>
      </link>
      <static>1</static>
      <allow_auto_disable>1</allow_auto_disable>
      <pose>0.030715 0.004529 0 0 -0 0</pose>
    </model>
    <state world_name='default'>
      <sim_time>559 610000000</sim_time>
      <real_time>217 972886554</real_time>
      <wall_time>1673623004 794881614</wall_time>
      <iterations>174393</iterations>
      <model name='ground_plane'>
        <pose>0 0 0 0 -0 0</pose>
        <scale>1 1 1</scale>
        <link name='link'>
          <pose>0 0 0 0 -0 0</pose>
          <velocity>0 0 0 0 -0 0</velocity>
          <acceleration>0 0 0 0 -0 0</acceleration>
          <wrench>0 0 0 0 -0 0</wrench>
        </link>
      </model>
      <model name='my_car'>
        <pose>5 2 0.099998 5e-06 -6e-06 0.000386</pose>
        <scale>1 1 1</scale>
        <link name='base_footprint'>
          <pose>5 2 0.099998 5e-06 -6e-06 0.000386</pose>
          <velocity>0.001456 0.001476 -0.002198 0.008569 -0.008464 0.000215</velocity>
          <acceleration>-0.649973 -0.651319 -2.39489 1.55717 -1.54645 0.352628</acceleration>
          <wrench>-2.64799 -2.65347 -9.75677 0 -0 0</wrench>
        </link>
        <link name='lower_left_wheel'>
          <pose>4.84994 2.14995 0.149998 -5e-06 0.000138 0.000386</pose>
          <velocity>0.001002 0.001014 -0.002163 0.011025 4e-06 0.000215</velocity>
          <acceleration>1.66903 1.67211 -2.28169 0.999361 0.006933 0.352719</acceleration>
          <wrench>0.641575 0.64276 -0.877083 0 -0 0</wrench>
        </link>
        <link name='lower_right_wheel'>
          <pose>4.85006 1.84994 0.149997 -3.14159 0.000102 0.000386</pose>
          <velocity>0.001065 0.001012 -0.004798 0.008988 3e-06 0.000214</velocity>
          <acceleration>1.77536 1.67235 -6.51168 1.44371 0.007157 0.353604</acceleration>
          <wrench>0.682447 0.642853 -2.50309 0 -0 0</wrench>
        </link>
        <link name='upper_left_wheel'>
          <pose>5.14994 2.15006 0.15 -6e-06 7.8e-05 0.000386</pose>
          <velocity>0.001001 0.001078 0.000352 -0.000157 -0 0.000214</velocity>
          <acceleration>1.66854 1.77971 1.96284 -1.37962 0.002507 0.353577</acceleration>
          <wrench>0.641385 0.684122 0.754516 0 -0 0</wrench>
        </link>
        <link name='upper_right_wheel'>
          <pose>5.15006 1.85006 0.149998 3.14158 2.1e-05 0.000386</pose>
          <velocity>0.001064 0.001079 -0.002161 0.011229 4e-06 0.000214</velocity>
          <acceleration>1.77571 1.77871 -2.32437 0.241088 0.006548 0.353977</acceleration>
          <wrench>0.682582 0.683737 -0.893489 0 -0 0</wrench>
        </link>
      </model>
      <model name='rmus_map_2'>
        <pose>-0.01 -0.01 0 0 -0 0</pose>
        <scale>1 1 1</scale>
        <link name='link_0'>
          <pose>-0.01 -0.01 0 0 -0 0</pose>
          <velocity>0 0 0 0 -0 0</velocity>
          <acceleration>0 0 0 0 -0 0</acceleration>
          <wrench>0 0 0 0 -0 0</wrench>
        </link>
      </model>
      <light name='sun'>
        <pose>0 0 10 0 -0 0</pose>
      </light>
    </state>
    <gui fullscreen='0'>
      <camera name='user_camera'>
        <pose>5.5917 3.83025 0.465888 0 0.149798 -2.10697</pose>
        <view_controller>orbit</view_controller>
        <projection_type>perspective</projection_type>
      </camera>
    </gui>
    <audio>
      <device>default</device>
    </audio>
    <model name='my_car'>
      <link name='base_footprint'>
        <inertial>
          <pose>-0.0077 -0 0.21807 0 -0 0</pose>
          <mass>4.074</mass>
          <inertia>
            <ixx>0.365722</ixx>
            <ixy>6.67858e-21</ixy>
            <ixz>-0.00531101</ixz>
            <iyy>0.406066</iyy>
            <iyz>-1.22636e-19</iyz>
            <izz>0.0834312</izz>
          </inertia>
        </inertial>
        <collision name='base_footprint_fixed_joint_lump__base_link_collision'>
          <pose>0 0 0.05 0 -0 0</pose>
          <geometry>
            <mesh>
              <scale>0.001 0.001 0.001</scale>
              <uri>file:////media/tdt/YI/ZY_RoboRTS/install/genshin_simulation/share/genshin_simulation/../../../../src/genshin_simulation/meshes/nexus_base_link_collision.STL</uri>
            </mesh>
          </geometry>
          <surface>
            <contact>
              <ode/>
            </contact>
            <friction>
              <ode/>
              <torsional>
                <ode/>
              </torsional>
            </friction>
            <bounce/>
          </surface>
          <max_contacts>10</max_contacts>
        </collision>
        <collision name='base_footprint_fixed_joint_lump__imu_collision_1'>
          <pose>0 0 0.06 0 -0 0</pose>
          <geometry>
            <box>
              <size>0.005 0.005 0.005</size>
            </box>
          </geometry>
          <surface>
            <contact>
              <ode/>
            </contact>
            <friction>
              <ode/>
              <torsional>
                <ode/>
              </torsional>
            </friction>
            <bounce/>
          </surface>
          <max_contacts>10</max_contacts>
        </collision>
        <collision name='base_footprint_fixed_joint_lump__lower_left_wheel_shaft_collision_2'>
          <pose>-0.15 0.108 0.05 0 -0 0</pose>
          <geometry>
            <mesh>
              <scale>0.001 0.001 0.001</scale>
              <uri>file:////media/tdt/YI/ZY_RoboRTS/install/genshin_simulation/share/genshin_simulation/../../../../src/genshin_simulation/meshes/wheel_shaft.STL</uri>
            </mesh>
          </geometry>
          <surface>
            <contact>
              <ode/>
            </contact>
            <friction>
              <ode/>
              <torsional>
                <ode/>
              </torsional>
            </friction>
            <bounce/>
          </surface>
          <max_contacts>10</max_contacts>
        </collision>
        <collision name='base_footprint_fixed_joint_lump__lower_right_wheel_shaft_collision_3'>
          <pose>-0.15 -0.108 0.05 3.14159 -0 0</pose>
          <geometry>
            <mesh>
              <scale>0.001 0.001 0.001</scale>
              <uri>file:////media/tdt/YI/ZY_RoboRTS/install/genshin_simulation/share/genshin_simulation/../../../../src/genshin_simulation/meshes/wheel_shaft.STL</uri>
            </mesh>
          </geometry>
          <surface>
            <contact>
              <ode/>
            </contact>
            <friction>
              <ode/>
              <torsional>
                <ode/>
              </torsional>
            </friction>
            <bounce/>
          </surface>
          <max_contacts>10</max_contacts>
        </collision>
        <collision name='base_footprint_fixed_joint_lump__upper_left_wheel_shaft_collision_4'>
          <pose>0.15 0.108 0.05 0 -0 0</pose>
          <geometry>
            <mesh>
              <scale>0.001 0.001 0.001</scale>
              <uri>file:////media/tdt/YI/ZY_RoboRTS/install/genshin_simulation/share/genshin_simulation/../../../../src/genshin_simulation/meshes/wheel_shaft.STL</uri>
            </mesh>
          </geometry>
          <surface>
            <contact>
              <ode/>
            </contact>
            <friction>
              <ode/>
              <torsional>
                <ode/>
              </torsional>
            </friction>
            <bounce/>
          </surface>
          <max_contacts>10</max_contacts>
        </collision>
        <collision name='base_footprint_fixed_joint_lump__upper_right_wheel_shaft_collision_5'>
          <pose>0.15 -0.108 0.05 3.14159 -0 0</pose>
          <geometry>
            <mesh>
              <scale>0.001 0.001 0.001</scale>
              <uri>file:////media/tdt/YI/ZY_RoboRTS/install/genshin_simulation/share/genshin_simulation/../../../../src/genshin_simulation/meshes/wheel_shaft.STL</uri>
            </mesh>
          </geometry>
          <surface>
            <contact>
              <ode/>
            </contact>
            <friction>
              <ode/>
              <torsional>
                <ode/>
              </torsional>
            </friction>
            <bounce/>
          </surface>
          <max_contacts>10</max_contacts>
        </collision>
        <collision name='base_footprint_fixed_joint_lump__velodyne2_base_link_collision_6'>
          <pose>0 0 0.72212 0 -0 0</pose>
          <geometry>
            <cylinder>
              <length>0.14424</length>
              <radius>0.04267</radius>
            </cylinder>
          </geometry>
          <max_contacts>10</max_contacts>
          <surface>
            <contact>
              <ode/>
            </contact>
            <bounce/>
            <friction>
              <torsional>
                <ode/>
              </torsional>
              <ode/>
            </friction>
          </surface>
        </collision>
        <visual name='base_footprint_fixed_joint_lump__base_link_visual'>
          <pose>0 0 0.05 0 -0 0</pose>
          <geometry>
            <mesh>
              <scale>0.001 0.001 0.001</scale>
              <uri>file:////media/tdt/YI/ZY_RoboRTS/install/genshin_simulation/share/genshin_simulation/../../../../src/genshin_simulation/meshes/nexus_base_link.STL</uri>
            </mesh>
          </geometry>
          <material>
            <script>
              <name>Gazebo/LightBlueLaser</name>
              <uri>file://media/materials/scripts/gazebo.material</uri>
            </script>
          </material>
        </visual>
        <visual name='base_footprint_fixed_joint_lump__imu_visual_1'>
          <pose>0 0 0.06 0 -0 0</pose>
          <geometry>
            <box>
              <size>0.005 0.005 0.005</size>
            </box>
          </geometry>
        </visual>
        <visual name='base_footprint_fixed_joint_lump__lower_left_wheel_shaft_visual_2'>
          <pose>-0.15 0.108 0.05 0 -0 0</pose>
          <geometry>
            <mesh>
              <scale>0.001 0.001 0.001</scale>
              <uri>file:////media/tdt/YI/ZY_RoboRTS/install/genshin_simulation/share/genshin_simulation/../../../../src/genshin_simulation/meshes/wheel_shaft.STL</uri>
            </mesh>
          </geometry>
          <material>
            <script>
              <name>Gazebo/TurquoiseGlowOutline</name>
              <uri>file://media/materials/scripts/gazebo.material</uri>
            </script>
          </material>
        </visual>
        <visual name='base_footprint_fixed_joint_lump__lower_right_wheel_shaft_visual_3'>
          <pose>-0.15 -0.108 0.05 3.14159 -0 0</pose>
          <geometry>
            <mesh>
              <scale>0.001 0.001 0.001</scale>
              <uri>file:////media/tdt/YI/ZY_RoboRTS/install/genshin_simulation/share/genshin_simulation/../../../../src/genshin_simulation/meshes/wheel_shaft.STL</uri>
            </mesh>
          </geometry>
          <material>
            <script>
              <name>Gazebo/TurquoiseGlowOutline</name>
              <uri>file://media/materials/scripts/gazebo.material</uri>
            </script>
          </material>
        </visual>
        <visual name='base_footprint_fixed_joint_lump__upper_left_wheel_shaft_visual_4'>
          <pose>0.15 0.108 0.05 0 -0 0</pose>
          <geometry>
            <mesh>
              <scale>0.001 0.001 0.001</scale>
              <uri>file:////media/tdt/YI/ZY_RoboRTS/install/genshin_simulation/share/genshin_simulation/../../../../src/genshin_simulation/meshes/wheel_shaft.STL</uri>
            </mesh>
          </geometry>
          <material>
            <script>
              <name>Gazebo/TurquoiseGlowOutline</name>
              <uri>file://media/materials/scripts/gazebo.material</uri>
            </script>
          </material>
        </visual>
        <visual name='base_footprint_fixed_joint_lump__upper_right_wheel_shaft_visual_5'>
          <pose>0.15 -0.108 0.05 3.14159 -0 0</pose>
          <geometry>
            <mesh>
              <scale>0.001 0.001 0.001</scale>
              <uri>file:////media/tdt/YI/ZY_RoboRTS/install/genshin_simulation/share/genshin_simulation/../../../../src/genshin_simulation/meshes/wheel_shaft.STL</uri>
            </mesh>
          </geometry>
          <material>
            <script>
              <name>Gazebo/TurquoiseGlowOutline</name>
              <uri>file://media/materials/scripts/gazebo.material</uri>
            </script>
          </material>
        </visual>
        <visual name='base_footprint_fixed_joint_lump__velodyne2_base_link_visual_6'>
          <pose>0 0 0.65 0 -0 0</pose>
          <geometry>
            <mesh>
              <scale>1 1 1</scale>
              <uri>/media/tdt/YI/ZY_RoboRTS/install/genshin_simulation/share/genshin_simulation/../../../../src/genshin_simulation/meshes/HDL32E_base.dae</uri>
            </mesh>
          </geometry>
        </visual>
        <visual name='base_footprint_fixed_joint_lump__velodyne2_visual_7'>
          <pose>0 0 0.65 0 -0 0</pose>
          <geometry>
            <mesh>
              <scale>1 1 1</scale>
              <uri>/media/tdt/YI/ZY_RoboRTS/install/genshin_simulation/share/genshin_simulation/../../../../src/genshin_simulation/meshes/HDL32E_scan.dae</uri>
            </mesh>
          </geometry>
        </visual>
        <gravity>1</gravity>
        <sensor name='imu_sensor' type='imu'>
          <plugin name='imu_plugin' filename='libgazebo_ros_imu_sensor.so'>
            <ros>
              <namespace>/</namespace>
              <remapping>~/out:=imu</remapping>
            </ros>
            <initial_orientation_as_reference>0</initial_orientation_as_reference>
          </plugin>
          <always_on>1</always_on>
          <update_rate>100</update_rate>
          <visualize>1</visualize>
          <imu>
            <angular_velocity>
              <x>
                <noise type='gaussian'>
                  <mean>0</mean>
                  <stddev>0.0002</stddev>
                  <bias_mean>7.5e-06</bias_mean>
                  <bias_stddev>8e-07</bias_stddev>
                </noise>
              </x>
              <y>
                <noise type='gaussian'>
                  <mean>0</mean>
                  <stddev>0.0002</stddev>
                  <bias_mean>7.5e-06</bias_mean>
                  <bias_stddev>8e-07</bias_stddev>
                </noise>
              </y>
              <z>
                <noise type='gaussian'>
                  <mean>0</mean>
                  <stddev>0.0002</stddev>
                  <bias_mean>7.5e-06</bias_mean>
                  <bias_stddev>8e-07</bias_stddev>
                </noise>
              </z>
            </angular_velocity>
            <linear_acceleration>
              <x>
                <noise type='gaussian'>
                  <mean>0</mean>
                  <stddev>0.017</stddev>
                  <bias_mean>0.1</bias_mean>
                  <bias_stddev>0.001</bias_stddev>
                </noise>
              </x>
              <y>
                <noise type='gaussian'>
                  <mean>0</mean>
                  <stddev>0.017</stddev>
                  <bias_mean>0.1</bias_mean>
                  <bias_stddev>0.001</bias_stddev>
                </noise>
              </y>
              <z>
                <noise type='gaussian'>
                  <mean>0</mean>
                  <stddev>0.017</stddev>
                  <bias_mean>0.1</bias_mean>
                  <bias_stddev>0.001</bias_stddev>
                </noise>
              </z>
            </linear_acceleration>
          </imu>
          <pose>0 0 0.06 0 -0 0</pose>
        </sensor>
        <sensor name='velodyne2-HDL32E' type='ray'>
          <visualize>0</visualize>
          <update_rate>15</update_rate>
          <ray>
            <scan>
              <horizontal>
                <samples>220</samples>
                <resolution>1</resolution>
                <min_angle>-3.14159</min_angle>
                <max_angle>3.14159</max_angle>
              </horizontal>
              <vertical>
                <samples>32</samples>
                <resolution>1</resolution>
                <min_angle>-0.535292</min_angle>
                <max_angle>0.186227</max_angle>
              </vertical>
            </scan>
            <range>
              <min>0.3</min>
              <max>131</max>
              <resolution>0.001</resolution>
            </range>
            <noise>
              <type>gaussian</type>
              <mean>0</mean>
              <stddev>0</stddev>
            </noise>
          </ray>
          <plugin name='gazebo_ros_laser_controller' filename='libgazebo_ros_velodyne_laser.so'>
            <ros>
              <namespace>/</namespace>
              <remapping>~/out:=velodyne_points2</remapping>
            </ros>
            <topicName>velodyne_points2</topicName>
            <frameName>velodyne2</frameName>
            <organize_cloud>0</organize_cloud>
            <min_range>0.9</min_range>
            <max_range>130.0</max_range>
            <gaussianNoise>0.008</gaussianNoise>
          </plugin>
          <pose>0 0 0.74081 0 -0 0</pose>
        </sensor>
        <self_collide>0</self_collide>
        <enable_wind>0</enable_wind>
        <kinematic>0</kinematic>
      </link>
      <joint name='lower_left_wheel_joint' type='revolute'>
        <pose relative_to='base_footprint'>-0.15 0.15 0.05 0 -0 0</pose>
        <parent>base_footprint</parent>
        <child>lower_left_wheel</child>
        <axis>
          <xyz>0 1 0</xyz>
          <limit>
            <lower>-1e+16</lower>
            <upper>1e+16</upper>
          </limit>
          <dynamics>
            <spring_reference>0</spring_reference>
            <spring_stiffness>0</spring_stiffness>
          </dynamics>
        </axis>
      </joint>
      <link name='lower_left_wheel'>
        <pose relative_to='lower_left_wheel_joint'>0 0 0 0 -0 0</pose>
        <inertial>
          <pose>0 0 0 0 -0 0</pose>
          <mass>0.3844</mass>
          <inertia>
            <ixx>0.000324824</ixx>
            <ixy>0</ixy>
            <ixz>0</ixz>
            <iyy>0.00048</iyy>
            <iyz>0</iyz>
            <izz>0.000324824</izz>
          </inertia>
        </inertial>
        <collision name='lower_left_wheel_collision'>
          <pose>0 0 0 1.5708 -0 0</pose>
          <geometry>
            <cylinder>
              <length>0.0505</length>
              <radius>0.05</radius>
            </cylinder>
          </geometry>
          <surface>
            <contact>
              <ode/>
            </contact>
            <friction>
              <ode>
                <mu>0</mu>
                <mu2>0</mu2>
              </ode>
              <torsional>
                <ode/>
              </torsional>
            </friction>
            <bounce/>
          </surface>
          <max_contacts>10</max_contacts>
        </collision>
        <visual name='lower_left_wheel_visual'>
          <pose>0 0 0 0 -0 0</pose>
          <geometry>
            <mesh>
              <scale>0.001 0.001 0.001</scale>
              <uri>file:////media/tdt/YI/ZY_RoboRTS/install/genshin_simulation/share/genshin_simulation/../../../../src/genshin_simulation/meshes/mecanum_wheel_right.STL</uri>
            </mesh>
          </geometry>
          <material>
            <script>
              <name>Gazebo/Turquoise</name>
              <uri>file://media/materials/scripts/gazebo.material</uri>
            </script>
          </material>
        </visual>
        <self_collide>0</self_collide>
        <enable_wind>0</enable_wind>
        <kinematic>0</kinematic>
      </link>
      <joint name='lower_right_wheel_joint' type='revolute'>
        <pose relative_to='base_footprint'>-0.15 -0.15 0.05 3.14159 -0 0</pose>
        <parent>base_footprint</parent>
        <child>lower_right_wheel</child>
        <axis>
          <xyz>0 1 0</xyz>
          <limit>
            <lower>-1e+16</lower>
            <upper>1e+16</upper>
          </limit>
          <dynamics>
            <spring_reference>0</spring_reference>
            <spring_stiffness>0</spring_stiffness>
          </dynamics>
        </axis>
      </joint>
      <link name='lower_right_wheel'>
        <pose relative_to='lower_right_wheel_joint'>0 0 0 0 -0 0</pose>
        <inertial>
          <pose>0 0 0 0 -0 0</pose>
          <mass>0.3844</mass>
          <inertia>
            <ixx>0.000324824</ixx>
            <ixy>0</ixy>
            <ixz>0</ixz>
            <iyy>0.00048</iyy>
            <iyz>0</iyz>
            <izz>0.000324824</izz>
          </inertia>
        </inertial>
        <collision name='lower_right_wheel_collision'>
          <pose>0 0 0 1.5708 -0 0</pose>
          <geometry>
            <cylinder>
              <length>0.0505</length>
              <radius>0.05</radius>
            </cylinder>
          </geometry>
          <surface>
            <contact>
              <ode/>
            </contact>
            <friction>
              <ode>
                <mu>0</mu>
                <mu2>0</mu2>
              </ode>
              <torsional>
                <ode/>
              </torsional>
            </friction>
            <bounce/>
          </surface>
          <max_contacts>10</max_contacts>
        </collision>
        <visual name='lower_right_wheel_visual'>
          <pose>0 0 0 0 -0 0</pose>
          <geometry>
            <mesh>
              <scale>0.001 0.001 0.001</scale>
              <uri>file:////media/tdt/YI/ZY_RoboRTS/install/genshin_simulation/share/genshin_simulation/../../../../src/genshin_simulation/meshes/mecanum_wheel_left.STL</uri>
            </mesh>
          </geometry>
          <material>
            <script>
              <name>Gazebo/Turquoise</name>
              <uri>file://media/materials/scripts/gazebo.material</uri>
            </script>
          </material>
        </visual>
        <self_collide>0</self_collide>
        <enable_wind>0</enable_wind>
        <kinematic>0</kinematic>
      </link>
      <joint name='upper_left_wheel_joint' type='revolute'>
        <pose relative_to='base_footprint'>0.15 0.15 0.05 0 -0 0</pose>
        <parent>base_footprint</parent>
        <child>upper_left_wheel</child>
        <axis>
          <xyz>0 1 0</xyz>
          <limit>
            <lower>-1e+16</lower>
            <upper>1e+16</upper>
          </limit>
          <dynamics>
            <spring_reference>0</spring_reference>
            <spring_stiffness>0</spring_stiffness>
          </dynamics>
        </axis>
      </joint>
      <link name='upper_left_wheel'>
        <pose relative_to='upper_left_wheel_joint'>0 0 0 0 -0 0</pose>
        <inertial>
          <pose>0 0 0 0 -0 0</pose>
          <mass>0.3844</mass>
          <inertia>
            <ixx>0.000324824</ixx>
            <ixy>0</ixy>
            <ixz>0</ixz>
            <iyy>0.00048</iyy>
            <iyz>0</iyz>
            <izz>0.000324824</izz>
          </inertia>
        </inertial>
        <collision name='upper_left_wheel_collision'>
          <pose>0 0 0 1.5708 -0 0</pose>
          <geometry>
            <cylinder>
              <length>0.0505</length>
              <radius>0.05</radius>
            </cylinder>
          </geometry>
          <surface>
            <contact>
              <ode/>
            </contact>
            <friction>
              <ode>
                <mu>0</mu>
                <mu2>0</mu2>
              </ode>
              <torsional>
                <ode/>
              </torsional>
            </friction>
            <bounce/>
          </surface>
          <max_contacts>10</max_contacts>
        </collision>
        <visual name='upper_left_wheel_visual'>
          <pose>0 0 0 0 -0 0</pose>
          <geometry>
            <mesh>
              <scale>0.001 0.001 0.001</scale>
              <uri>file:////media/tdt/YI/ZY_RoboRTS/install/genshin_simulation/share/genshin_simulation/../../../../src/genshin_simulation/meshes/mecanum_wheel_left.STL</uri>
            </mesh>
          </geometry>
          <material>
            <script>
              <name>Gazebo/Turquoise</name>
              <uri>file://media/materials/scripts/gazebo.material</uri>
            </script>
          </material>
        </visual>
        <self_collide>0</self_collide>
        <enable_wind>0</enable_wind>
        <kinematic>0</kinematic>
      </link>
      <joint name='upper_right_wheel_joint' type='revolute'>
        <pose relative_to='base_footprint'>0.15 -0.15 0.05 3.14159 -0 0</pose>
        <parent>base_footprint</parent>
        <child>upper_right_wheel</child>
        <axis>
          <xyz>0 1 0</xyz>
          <limit>
            <lower>-1e+16</lower>
            <upper>1e+16</upper>
          </limit>
          <dynamics>
            <spring_reference>0</spring_reference>
            <spring_stiffness>0</spring_stiffness>
          </dynamics>
        </axis>
      </joint>
      <link name='upper_right_wheel'>
        <pose relative_to='upper_right_wheel_joint'>0 0 0 0 -0 0</pose>
        <inertial>
          <pose>0 0 0 0 -0 0</pose>
          <mass>0.3844</mass>
          <inertia>
            <ixx>0.000324824</ixx>
            <ixy>0</ixy>
            <ixz>0</ixz>
            <iyy>0.00048</iyy>
            <iyz>0</iyz>
            <izz>0.000324824</izz>
          </inertia>
        </inertial>
        <collision name='upper_right_wheel_collision'>
          <pose>0 0 0 1.5708 -0 0</pose>
          <geometry>
            <cylinder>
              <length>0.0505</length>
              <radius>0.05</radius>
            </cylinder>
          </geometry>
          <surface>
            <contact>
              <ode/>
            </contact>
            <friction>
              <ode>
                <mu>0</mu>
                <mu2>0</mu2>
              </ode>
              <torsional>
                <ode/>
              </torsional>
            </friction>
            <bounce/>
          </surface>
          <max_contacts>10</max_contacts>
        </collision>
        <visual name='upper_right_wheel_visual'>
          <pose>0 0 0 0 -0 0</pose>
          <geometry>
            <mesh>
              <scale>0.001 0.001 0.001</scale>
              <uri>file:////media/tdt/YI/ZY_RoboRTS/install/genshin_simulation/share/genshin_simulation/../../../../src/genshin_simulation/meshes/mecanum_wheel_right.STL</uri>
            </mesh>
          </geometry>
          <material>
            <script>
              <name>Gazebo/Turquoise</name>
              <uri>file://media/materials/scripts/gazebo.material</uri>
            </script>
          </material>
        </visual>
        <self_collide>0</self_collide>
        <enable_wind>0</enable_wind>
        <kinematic>0</kinematic>
      </link>
      <static>0</static>
      <plugin name='object_controller' filename='libgazebo_ros_planar_move.so'>
        <commandTopic>cmd_vel</commandTopic>
        <odometryTopic>odom</odometryTopic>
        <odometryFrame>odom</odometryFrame>
        <odometryRate>30.0</odometryRate>
        <robotBaseFrame>base_footprint</robotBaseFrame>
        <broadcastTF>1</broadcastTF>
      </plugin>
      <plugin name='robot_joint_state' filename='libgazebo_ros_joint_state_publisher.so'>
        <ros>
          <remapping>~/out:=joint_states</remapping>
        </ros>
        <update_rate>30</update_rate>
        <joint_name>lower_right_wheel_joint</joint_name>
        <joint_name>lower_left_wheel_joint</joint_name>
        <joint_name>upper_right_wheel_joint</joint_name>
        <joint_name>upper_left_wheel_joint</joint_name>
      </plugin>
      <pose>5 2 1 0 -0 0</pose>
    </model>
  </world>
</sdf>
